<html><head><meta charset='utf-8'><meta name='viewport' content='width=device-width, initial-scale=1'>
<meta name='applicable-device' content='pc'><meta name='keywords' content='电脑,电脑讲解,电脑技术,编程,电脑故障维修Java自学-异常处理 处理' />
<script src='../../highlight/highlight.pack.js'></script>
<link rel='stylesheet' type='text/css' href='../../highlight/styles/monokai.css'/>

<link rel='stylesheet' href='../../fenxiang/dist/css/share.min.css'>
<script src='../../fenxiang/src/js/social-share.js'></script>
<script src='../../fenxiang/src/js/qrcode.js'></script>

</head><body><script>hljs.initHighlightingOnLoad();</script><script>
var system ={};  
var p = navigator.platform;       
system.win = p.indexOf('Win') == 0;  
system.mac = p.indexOf('Mac') == 0;  
system.x11 = (p == 'X11') || (p.indexOf('Linux') == 0);     
if(system.win||system.mac||system.xll){
document.write("<link href='../css/3.css' rel='stylesheet' type='text/css'>");}else{ document.write("<link href='../css/3wap.css' rel='stylesheet' type='text/css'>");}</script><script src='../../js/3.js'></script><div class='div2'><div class='heading_nav'><ul><div><li><a href='../../index.html'>首页</a></li>
</div><div onclick='hidden1()' >分享</div>
</ul></div></div>
<div id='heading_nav2'> 
<li class='row' >
<div class='social-share' data-mode='prepend'><a href='javascript:' class='social-share-icon icon-heart'></a></div></li></div><script charset='utf-8' src='../../3/js/hengfu.js'></script><script charset='utf-8' src='../../3/js/hengfu2.js'></script><hr><div class='div1'><div class='biaoti'><center>Java自学-异常处理 处理</center></div><div class='banquan'>原文出处:本文由博客园博主半米高峰提供。<br/>
原文连接:https://www.cnblogs.com/jeddzd/p/11664724.html</div><br>
    <h2 id="java的异常处理办法-try-catch-throws">Java的异常处理办法 try catch throws</h2>
<p>异常处理常见手段： try catch finally throws</p>
<p>步骤 1 : <strong>try catch</strong></p>
<p>1.将可能抛出FileNotFoundException <strong>文件不存在异常</strong>的代码放在try里<br />
2.如果文件存在，就会顺序往下执行，并且不执行catch块中的代码</p>
<ol>
<li>如果文件不存在，try 里的代码会立即终止，程序流程会运行到对应的catch块中</li>
<li>e.printStackTrace(); 会打印出方法的调用痕迹，如此例，会打印出异常开始于TestException的第16行，这样就便于定位和分析到底哪里出了异常<br />
<img src="./images/Java自学-异常处理 处理0.png" alt="try catch" /></li>
</ol>
<pre><code><code>package exception;
 
import java.io.File;
import java.io.FileInputStream;
import java.io.FileNotFoundException;
 
public class TestException {
 
    public static void main(String[] args) {
         
        File f= new File(&quot;d:/LOL.exe&quot;);
         
        try{
            System.out.println(&quot;试图打开 d:/LOL.exe&quot;);
            new FileInputStream(f);
            System.out.println(&quot;成功打开&quot;);
        }
        catch(FileNotFoundException e){
            System.out.println(&quot;d:/LOL.exe不存在&quot;);
            e.printStackTrace();
        }
         
    }
}</code></code></pre>
<p>步骤 2 : <strong>使用异常的父类进行catch</strong></p>
<p>FileNotFoundException是Exception的子类，使用Exception也可以catch住FileNotFoundException</p>
<pre><code><code>package exception;
  
import java.io.File;
import java.io.FileInputStream;
import java.io.FileNotFoundException;
  
public class TestException {
  
    public static void main(String[] args) {
          
        File f= new File(&quot;d:/LOL.exe&quot;);
          
        try{
            System.out.println(&quot;试图打开 d:/LOL.exe&quot;);
            new FileInputStream(f);
            System.out.println(&quot;成功打开&quot;);
        }
         
        catch(Exception e){
            System.out.println(&quot;d:/LOL.exe不存在&quot;);
            e.printStackTrace();
        }
          
    }
}</code></code></pre>
<p>步骤 3 : <strong>多异常捕捉办法1</strong></p>
<p>有的时候一段代码会抛出多种异常，比如</p>
<pre><code><code>new FileInputStream(f);
Date d = sdf.parse(&quot;2016-06-03&quot;);</code></code></pre>
<p>这段代码，会抛出 文件不存在异常 FileNotFoundException 和 解析异常ParseException<br />
解决办法之一是分别进行catch</p>
<pre><code><code>package exception;
 
import java.io.File;
import java.io.FileInputStream;
import java.io.FileNotFoundException;
import java.text.ParseException;
import java.text.SimpleDateFormat;
import java.util.Date;
 
public class TestException {
 
    public static void main(String[] args) {
 
        File f = new File(&quot;d:/LOL.exe&quot;);
 
        try {
            System.out.println(&quot;试图打开 d:/LOL.exe&quot;);
            new FileInputStream(f);
            System.out.println(&quot;成功打开&quot;);
            SimpleDateFormat sdf = new SimpleDateFormat(&quot;yyyy-MM-dd&quot;);
            Date d = sdf.parse(&quot;2016-06-03&quot;);
        } catch (FileNotFoundException e) {
            System.out.println(&quot;d:/LOL.exe不存在&quot;);
            e.printStackTrace();
        } catch (ParseException e) {
            System.out.println(&quot;日期格式解析错误&quot;);
            e.printStackTrace();
        }
    }
}</code></code></pre>
<p>步骤 4 : <strong>多异常捕捉办法2</strong></p>
<p>另一个种办法是把多个异常，放在一个catch里统一捕捉<br />
catch (FileNotFoundException | ParseException e) {}</p>
<p>这种方式从 JDK7开始支持，好处是捕捉的代码<strong>更紧凑</strong>，不足之处是，一旦发生异常，<strong>不能确定到底是哪种异常</strong>，需要通过instanceof 判断具体的异常类型</p>
<pre><code><code>package exception;
 
import java.io.File;
import java.io.FileInputStream;
import java.io.FileNotFoundException;
import java.text.ParseException;
import java.text.SimpleDateFormat;
import java.util.Date;
 
public class TestException {
 
    public static void main(String[] args) {
 
        File f = new File(&quot;d:/LOL.exe&quot;);
 
        try {
            System.out.println(&quot;试图打开 d:/LOL.exe&quot;);
            new FileInputStream(f);
            System.out.println(&quot;成功打开&quot;);
            SimpleDateFormat sdf = new SimpleDateFormat(&quot;yyyy-MM-dd&quot;);
            Date d = sdf.parse(&quot;2016-06-03&quot;);
        } catch (FileNotFoundException | ParseException e) {
            if (e instanceof FileNotFoundException)
                System.out.println(&quot;d:/LOL.exe不存在&quot;);
            if (e instanceof ParseException)
                System.out.println(&quot;日期格式解析错误&quot;);
 
            e.printStackTrace();
        }
 
    }
}</code></code></pre>
<p>步骤 5 : <strong>finally</strong></p>
<p>无论是否出现异常，finally中的代码都会被执行</p>
<pre><code><code>package exception;
 
import java.io.File;
import java.io.FileInputStream;
import java.io.FileNotFoundException;
 
public class TestException {
 
    public static void main(String[] args) {
         
        File f= new File(&quot;d:/LOL.exe&quot;);
         
        try{
            System.out.println(&quot;试图打开 d:/LOL.exe&quot;);
            new FileInputStream(f);
            System.out.println(&quot;成功打开&quot;);
        }
        catch(FileNotFoundException e){
            System.out.println(&quot;d:/LOL.exe不存在&quot;);
            e.printStackTrace();
        }
        finally{
            System.out.println(&quot;无论文件是否存在， 都会执行的代码&quot;);
        }
    }
}</code></code></pre>
<p>步骤 6 : <strong>throws</strong></p>
<p>考虑如下情况：<br />
主方法调用method1<br />
method1调用method2<br />
method2中打开文件</p>
<p>method2中需要进行异常处理<br />
但是method2<strong>不打算处理</strong>，而是把这个异常<strong>通过throws抛出去</strong><br />
那么method1就会<strong>接到该异常</strong>。 处理办法也是两种，要么是try catch处理掉，要么也是<strong>抛出去</strong>。<br />
method1选择本地try catch住 一旦try catch住了，就相当于把这个异常消化掉了，主方法在调用method1的时候，就不需要进行异常处理了</p>
<pre><code><code>package exception;
 
import java.io.File;
import java.io.FileInputStream;
import java.io.FileNotFoundException;
 
public class TestException {
 
    public static void main(String[] args) {
        method1();
 
    }
 
    private static void method1() {
        try {
            method2();
        } catch (FileNotFoundException e) {
            // TODO Auto-generated catch block
            e.printStackTrace();
        }
 
    }
 
    private static void method2() throws FileNotFoundException {
 
        File f = new File(&quot;d:/LOL.exe&quot;);
 
        System.out.println(&quot;试图打开 d:/LOL.exe&quot;);
        new FileInputStream(f);
        System.out.println(&quot;成功打开&quot;);
 
    }
}</code></code></pre>
<p>步骤 7 : <strong>throw和throws的区别</strong></p>
<p>throws与throw这两个关键字接近，不过意义不一样，有如下区别：</p>
<ol>
<li>throws 出现在方法声明上，而throw通常都出现在方法体内。</li>
<li>throws 表示出现异常的一种可能性，并不一定会发生这些异常；throw则是抛出了异常，执行throw则一定抛出了某个异常对象。</li>
</ol>
<p><strong>练习</strong>： <a href="http://how2j.cn/k/exception/exception-trycatch/336.html?p=43278">异常处理</a></p>
<p>假设有一个方法 public int method()， 会返回一个整数<br />
在这个方法中有try catch 和 finally.<br />
try 里返回 1<br />
catch 里 返回 2<br />
finally 里 返回3<br />
那么，这个方法到底返回多少？</p>
<p><strong>答案</strong>：</p>
<pre><code><code>package exception;
 
public class TestException {
 
    public static int method() {
        try {
            return return1();
        } catch (Exception e) {
            return return2();
        } finally {
            return return3();
        }
    }
 
    private static int return1() {
        System.out.println(&quot;return 1&quot;);
        return 1;
    }
    private static int return2() {
        System.out.println(&quot;return 2&quot;);
        return 2;
    }
    private static int return3() {
        System.out.println(&quot;return 3&quot;);
        return 3;
    }
 
    public static void main(String[] args) {
        int result = method();
        System.out.println(&quot;result:&quot; + result);
         
    }
}</code></code></pre>
<p>可以看到，最后结果是取finally的返回值3.<br />
同时，故意把method设计成调用 return1(),return2(),return3()。<br />
可以观察到，try里的 返回和 finally的返回都是执行了的，不过最后选择使用finally里的返回的值</p>


</div><hr><script charset='utf-8' src='../../js/sming.js'></script></body></html>